<?xml version="1.0"?>
<robot xmlns:xacro="http://www.ros.org/wiki/xacro" name="firefighter" >

  <xacro:property name="width" value=".2" />

  <link name="dummy">
  </link>

  <link name="base">
    <visual>
      <geometry>
       <mesh filename="package://mycobot_description/urdf/mycobot_280/joint1.dae"/>
      </geometry>
      <origin xyz="0 0 0" rpy="0 0 -1.5708"/>
    </visual>
    <collision>
      <geometry>
       <mesh filename="package://mycobot_description/urdf/mycobot_280/joint1.dae"/>
      </geometry>
      <origin xyz="0.0 0 0" rpy="0 0 -1.5708"/>
    </collision>
    <inertial>
      <mass value="0.1" />
      <inertia ixx="1.0" ixy="0.0" ixz="0.0" iyy="1.0" iyz="0.0" izz="1.0" />
    </inertial>
  </link>

  <link name="link1">
    <visual>
      <geometry>
       <mesh filename="package://mycobot_description/urdf/mycobot_280/joint2.dae"/>
      </geometry>
      <origin xyz="0.0 0 -0.06096" rpy="0 0 -1.5708"/>
    </visual>
    <collision>
     <geometry>
       <mesh filename="package://mycobot_description/urdf/mycobot_280/joint2.dae"/>
      </geometry>
      <origin xyz="0.0 0 -0.06096" rpy="0 0 -1.5708"/>
    </collision>
    <inertial>
      <mass value="0.1" />
      <inertia ixx="1.0" ixy="0.0" ixz="0.0" iyy="1.0" iyz="0.0" izz="1.0" />
    </inertial>
  </link>

  <link name="link2">
    <visual>
      <geometry>
       <mesh filename="package://mycobot_description/urdf/mycobot_280/joint3.dae"/>
      </geometry>
    <origin xyz="0.0 0 0.03256" rpy="0 -1.5708 0"/>
    </visual>
    <collision>
      <geometry>
       <mesh filename="package://mycobot_description/urdf/mycobot_280/joint3.dae"/>
      </geometry>
      <origin xyz="0.0 0 0.03256" rpy="0 -1.5708 0"/>
    </collision>
    <inertial>
      <mass value="0.1" />
      <inertia ixx="1.0" ixy="0.0" ixz="0.0" iyy="1.0" iyz="0.0" izz="1.0" />
    </inertial>
  </link>

  <link name="link3">
    <visual>
      <geometry>
       <mesh filename="package://mycobot_description/urdf/mycobot_280/joint4.dae"/>
      </geometry>
      <origin xyz="0.0 0 0.03056" rpy="0 -1.5708 0"/>
    </visual>
    <collision>
      <geometry>
       <mesh filename="package://mycobot_description/urdf/mycobot_280/joint4.dae"/>
      </geometry>
      <origin xyz="0.0 0 0.03056" rpy="0 -1.5708 0"/>
    </collision>
    <inertial>
      <mass value="0.1" />
      <inertia ixx="1.0" ixy="0.0" ixz="0.0" iyy="1.0" iyz="0.0" izz="1.0" />
    </inertial>
  </link>

  <link name="link4">
    <visual>
      <geometry>
       <mesh filename="package://mycobot_description/urdf/mycobot_280/joint5_fixed.dae"/>
      </geometry>
    <origin xyz="0.0 0 -0.03356" rpy="0 -1.5708 1.5708"/>
    </visual>
    <collision>
      <geometry>
       <mesh filename="package://mycobot_description/urdf/mycobot_280/joint5_fixed.dae"/>
      </geometry>
      <origin xyz="0.0 0 -0.03356" rpy="0 -1.5708 1.5708"/>
    </collision>
    <inertial>
      <mass value="0.1" />
      <inertia ixx="1.0" ixy="0.0" ixz="0.0" iyy="1.0" iyz="0.0" izz="1.0" />
    </inertial>
  </link>

  <link name="link5">
    <visual>
      <geometry>
       <mesh filename="package://mycobot_description/urdf/mycobot_280/joint6.dae"/>
      </geometry>
    <origin xyz="0 0.00 -0.038" rpy="0 0 0"/>
    </visual>
    <collision>
      <geometry>
       <mesh filename="package://mycobot_description/urdf/mycobot_280/joint6.dae"/>
      </geometry>
      <origin xyz="0 0.00 -0.038" rpy="0 0 0"/>
    </collision>
    <inertial>
      <mass value="0.1" />
      <inertia ixx="1.0" ixy="0.0" ixz="0.0" iyy="1.0" iyz="0.0" izz="1.0" />
    </inertial>
  </link>

  <link name="link6">
    <visual>
      <geometry>
       <mesh filename="package://mycobot_description/urdf/mycobot_280/joint7.dae"/>
      </geometry>
    <origin xyz="0.0 0 -0.012" rpy="0 0 0"/>
    </visual>
    <collision>
      <geometry>
       <mesh filename="package://mycobot_description/urdf/mycobot_280/joint7.dae"/>
      </geometry>
      <origin xyz="0.0 0 -0.012" rpy="0 0 0"/>
    </collision>
    <inertial>
      <mass value="0.1" />
      <inertia ixx="1.0" ixy="0.0" ixz="0.0" iyy="1.0" iyz="0.0" izz="1.0" />
    </inertial>
  </link>

  <joint name="dummy_joint" type="fixed">
    <parent link="dummy"/>
    <child link="base"/>
  </joint>

  <joint name="link1_to_base" type="revolute">
    <axis xyz="0 0 1"/>
    <limit effort="1000.0" lower="-3.14" upper="3.14159" velocity="0"/>
    <parent link="base"/>
    <child link="link1"/>
    <origin xyz="0 0 0.13156" rpy="0 0 0"/>  
  </joint>

  <joint name="link2_to_link1" type="revolute">
    <axis xyz="0 0 1"/>
    <limit effort="1000.0" lower="-3.14" upper="3.14159" velocity="0"/>
    <parent link="link1"/>
    <child link="link2"/>
    <origin xyz="0 0  0" rpy="0 1.5708 -1.5708"/>  
  </joint>

  <joint name="link3_to_link2" type="revolute">
    <axis xyz="0 0 1"/>
    <limit effort="1000.0" lower="-3.14" upper="3.14159" velocity="0"/>
    <parent link="link2"/>
    <child link="link3"/>
    <origin xyz="  -0.1104 0 0 " rpy="0 0 0"/>  
  </joint>

  <joint name="link4_to_link3" type="revolute">
    <axis xyz="0 0 1"/>
    <limit effort="1000.0" lower="-3.14" upper="3.14159" velocity="0"/>
    <parent link="link3"/>
    <child link="link4"/>
    <origin xyz="-0.096 0 0.06462" rpy="0 0 -1.5708"/>  
  </joint>

  <joint name="link5_to_link4" type="revolute">
    <axis xyz="0 0 1"/>
    <limit effort="1000.0" lower="-3.14" upper="3.14159" velocity="0"/>
    <parent link="link4"/>
    <child link="link5"/>
    <origin xyz="0 -0.07318 0" rpy="1.5708 -1.5708 0"/>  
  </joint>

  <joint name="link6_to_link5" type="revolute">
    <axis xyz="0 0 1"/>
    <limit effort="1000.0" lower="-3.14" upper="3.14159" velocity="0"/>
    <parent link="link5"/>
    <child link="link6"/>
    <origin xyz="0 0.0456 0" rpy="-1.5708 0 0"/>  
  </joint>

</robot>

